2025-06-29 09:18:55,923 [INFO] Initializing ChessVsAI
2025-06-29 09:18:56,506 [INFO] Stockfish loaded successfully.
2025-06-29 09:18:59,002 [INFO] Clicked square: e2
2025-06-29 09:18:59,002 [INFO] Selected piece: P at e2
2025-06-29 09:19:00,659 [INFO] Clicked square: e4
2025-06-29 09:19:01,719 [INFO] Generating Ollama move for FEN: rnbqkbnr/pppppppp/8/8/4P3/8/PPPP1PPP/RNBQKBNR b KQkq - 0 1
2025-06-29 09:19:03,767 [ERROR] Ollama attempt 1 error: Failed to connect to Ollama. Please check that Ollama is downloaded, running and accessible. https://ollama.com/download
Traceback (most recent call last):
  File "C:\Users\HP\Desktop\Ollama-Chess_GUI\grok_chess.py", line 1170, in get_ollama_move
    response = ollama.generate(
               ^^^^^^^^^^^^^^^^
  File "C:\Users\HP\anaconda3\Lib\site-packages\ollama\_client.py", line 247, in generate
    return self._request(
           ^^^^^^^^^^^^^^
  File "C:\Users\HP\anaconda3\Lib\site-packages\ollama\_client.py", line 180, in _request
    return cls(**self._request_raw(*args, **kwargs).json())
                 ^^^^^^^^^^^^^^^^^^^^^^^^^^^^^^^^^^
  File "C:\Users\HP\anaconda3\Lib\site-packages\ollama\_client.py", line 126, in _request_raw
    raise ConnectionError(CONNECTION_ERROR_MESSAGE) from None
ConnectionError: Failed to connect to Ollama. Please check that Ollama is downloaded, running and accessible. https://ollama.com/download
2025-06-29 09:19:06,813 [ERROR] Ollama attempt 2 error: Failed to connect to Ollama. Please check that Ollama is downloaded, running and accessible. https://ollama.com/download
Traceback (most recent call last):
  File "C:\Users\HP\Desktop\Ollama-Chess_GUI\grok_chess.py", line 1170, in get_ollama_move
    response = ollama.generate(
               ^^^^^^^^^^^^^^^^
  File "C:\Users\HP\anaconda3\Lib\site-packages\ollama\_client.py", line 247, in generate
    return self._request(
           ^^^^^^^^^^^^^^
  File "C:\Users\HP\anaconda3\Lib\site-packages\ollama\_client.py", line 180, in _request
    return cls(**self._request_raw(*args, **kwargs).json())
                 ^^^^^^^^^^^^^^^^^^^^^^^^^^^^^^^^^^
  File "C:\Users\HP\anaconda3\Lib\site-packages\ollama\_client.py", line 126, in _request_raw
    raise ConnectionError(CONNECTION_ERROR_MESSAGE) from None
ConnectionError: Failed to connect to Ollama. Please check that Ollama is downloaded, running and accessible. https://ollama.com/download
2025-06-29 09:19:09,850 [ERROR] Ollama attempt 3 error: Failed to connect to Ollama. Please check that Ollama is downloaded, running and accessible. https://ollama.com/download
Traceback (most recent call last):
  File "C:\Users\HP\Desktop\Ollama-Chess_GUI\grok_chess.py", line 1170, in get_ollama_move
    response = ollama.generate(
               ^^^^^^^^^^^^^^^^
  File "C:\Users\HP\anaconda3\Lib\site-packages\ollama\_client.py", line 247, in generate
    return self._request(
           ^^^^^^^^^^^^^^
  File "C:\Users\HP\anaconda3\Lib\site-packages\ollama\_client.py", line 180, in _request
    return cls(**self._request_raw(*args, **kwargs).json())
                 ^^^^^^^^^^^^^^^^^^^^^^^^^^^^^^^^^^
  File "C:\Users\HP\anaconda3\Lib\site-packages\ollama\_client.py", line 126, in _request_raw
    raise ConnectionError(CONNECTION_ERROR_MESSAGE) from None
ConnectionError: Failed to connect to Ollama. Please check that Ollama is downloaded, running and accessible. https://ollama.com/download
2025-06-29 09:19:09,854 [ERROR] Ollama failed: Ollama failed to provide valid move
Traceback (most recent call last):
  File "C:\Users\HP\Desktop\Ollama-Chess_GUI\grok_chess.py", line 1082, in get_ai_move
    raise Exception("Ollama failed to provide valid move")
Exception: Ollama failed to provide valid move
2025-06-29 09:19:09,981 [INFO] Stockfish move: e7e5
2025-06-29 09:19:10,192 [INFO] AI move took 8.47 seconds
2025-06-29 09:19:12,489 [INFO] Clicked square: g1
2025-06-29 09:19:12,492 [INFO] Selected piece: N at g1
2025-06-29 09:19:13,622 [INFO] Clicked square: f3
2025-06-29 09:19:14,288 [INFO] Generating Ollama move for FEN: rnbqkbnr/pppp1ppp/8/4p3/4P3/5N2/PPPP1PPP/RNBQKB1R b KQkq - 1 2
2025-06-29 09:19:16,322 [ERROR] Ollama attempt 1 error: Failed to connect to Ollama. Please check that Ollama is downloaded, running and accessible. https://ollama.com/download
Traceback (most recent call last):
  File "C:\Users\HP\Desktop\Ollama-Chess_GUI\grok_chess.py", line 1170, in get_ollama_move
    response = ollama.generate(
               ^^^^^^^^^^^^^^^^
  File "C:\Users\HP\anaconda3\Lib\site-packages\ollama\_client.py", line 247, in generate
    return self._request(
           ^^^^^^^^^^^^^^
  File "C:\Users\HP\anaconda3\Lib\site-packages\ollama\_client.py", line 180, in _request
    return cls(**self._request_raw(*args, **kwargs).json())
                 ^^^^^^^^^^^^^^^^^^^^^^^^^^^^^^^^^^
  File "C:\Users\HP\anaconda3\Lib\site-packages\ollama\_client.py", line 126, in _request_raw
    raise ConnectionError(CONNECTION_ERROR_MESSAGE) from None
ConnectionError: Failed to connect to Ollama. Please check that Ollama is downloaded, running and accessible. https://ollama.com/download
2025-06-29 09:19:19,353 [ERROR] Ollama attempt 2 error: Failed to connect to Ollama. Please check that Ollama is downloaded, running and accessible. https://ollama.com/download
Traceback (most recent call last):
  File "C:\Users\HP\Desktop\Ollama-Chess_GUI\grok_chess.py", line 1170, in get_ollama_move
    response = ollama.generate(
               ^^^^^^^^^^^^^^^^
  File "C:\Users\HP\anaconda3\Lib\site-packages\ollama\_client.py", line 247, in generate
    return self._request(
           ^^^^^^^^^^^^^^
  File "C:\Users\HP\anaconda3\Lib\site-packages\ollama\_client.py", line 180, in _request
    return cls(**self._request_raw(*args, **kwargs).json())
                 ^^^^^^^^^^^^^^^^^^^^^^^^^^^^^^^^^^
  File "C:\Users\HP\anaconda3\Lib\site-packages\ollama\_client.py", line 126, in _request_raw
    raise ConnectionError(CONNECTION_ERROR_MESSAGE) from None
ConnectionError: Failed to connect to Ollama. Please check that Ollama is downloaded, running and accessible. https://ollama.com/download
2025-06-29 09:19:22,395 [ERROR] Ollama attempt 3 error: Failed to connect to Ollama. Please check that Ollama is downloaded, running and accessible. https://ollama.com/download
Traceback (most recent call last):
  File "C:\Users\HP\Desktop\Ollama-Chess_GUI\grok_chess.py", line 1170, in get_ollama_move
    response = ollama.generate(
               ^^^^^^^^^^^^^^^^
  File "C:\Users\HP\anaconda3\Lib\site-packages\ollama\_client.py", line 247, in generate
    return self._request(
           ^^^^^^^^^^^^^^
  File "C:\Users\HP\anaconda3\Lib\site-packages\ollama\_client.py", line 180, in _request
    return cls(**self._request_raw(*args, **kwargs).json())
                 ^^^^^^^^^^^^^^^^^^^^^^^^^^^^^^^^^^
  File "C:\Users\HP\anaconda3\Lib\site-packages\ollama\_client.py", line 126, in _request_raw
    raise ConnectionError(CONNECTION_ERROR_MESSAGE) from None
ConnectionError: Failed to connect to Ollama. Please check that Ollama is downloaded, running and accessible. https://ollama.com/download
2025-06-29 09:19:22,397 [ERROR] Ollama failed: Ollama failed to provide valid move
Traceback (most recent call last):
  File "C:\Users\HP\Desktop\Ollama-Chess_GUI\grok_chess.py", line 1082, in get_ai_move
    raise Exception("Ollama failed to provide valid move")
Exception: Ollama failed to provide valid move
2025-06-29 09:19:22,550 [INFO] Stockfish move: b8c6
2025-06-29 09:19:22,702 [INFO] AI move took 8.41 seconds
2025-06-29 19:14:12,363 [INFO] Initializing ChessVsAI
2025-06-29 19:14:12,868 [INFO] Stockfish loaded successfully.
2025-06-30 21:36:10,256 [INFO] Initializing ChessVsAI
2025-06-30 21:36:11,114 [INFO] Stockfish loaded successfully.
2025-06-30 21:36:13,874 [INFO] Clicked square: e2
2025-06-30 21:36:13,874 [INFO] Selected piece: P at e2
2025-06-30 21:36:14,815 [INFO] Clicked square: e4
2025-06-30 21:36:15,885 [INFO] Generating Ollama move for FEN: rnbqkbnr/pppppppp/8/8/4P3/8/PPPP1PPP/RNBQKBNR b KQkq - 0 1
2025-06-30 21:36:17,929 [ERROR] Ollama attempt 1 error: Failed to connect to Ollama. Please check that Ollama is downloaded, running and accessible. https://ollama.com/download
Traceback (most recent call last):
  File "C:\Users\HP\Desktop\Ollama-Chess_GUI\grok_chess.py", line 1170, in get_ollama_move
    response = ollama.generate(
               ^^^^^^^^^^^^^^^^
  File "C:\Users\HP\anaconda3\Lib\site-packages\ollama\_client.py", line 247, in generate
    return self._request(
           ^^^^^^^^^^^^^^
  File "C:\Users\HP\anaconda3\Lib\site-packages\ollama\_client.py", line 180, in _request
    return cls(**self._request_raw(*args, **kwargs).json())
                 ^^^^^^^^^^^^^^^^^^^^^^^^^^^^^^^^^^
  File "C:\Users\HP\anaconda3\Lib\site-packages\ollama\_client.py", line 126, in _request_raw
    raise ConnectionError(CONNECTION_ERROR_MESSAGE) from None
ConnectionError: Failed to connect to Ollama. Please check that Ollama is downloaded, running and accessible. https://ollama.com/download
2025-06-30 21:36:21,003 [ERROR] Ollama attempt 2 error: Failed to connect to Ollama. Please check that Ollama is downloaded, running and accessible. https://ollama.com/download
Traceback (most recent call last):
  File "C:\Users\HP\Desktop\Ollama-Chess_GUI\grok_chess.py", line 1170, in get_ollama_move
    response = ollama.generate(
               ^^^^^^^^^^^^^^^^
  File "C:\Users\HP\anaconda3\Lib\site-packages\ollama\_client.py", line 247, in generate
    return self._request(
           ^^^^^^^^^^^^^^
  File "C:\Users\HP\anaconda3\Lib\site-packages\ollama\_client.py", line 180, in _request
    return cls(**self._request_raw(*args, **kwargs).json())
                 ^^^^^^^^^^^^^^^^^^^^^^^^^^^^^^^^^^
  File "C:\Users\HP\anaconda3\Lib\site-packages\ollama\_client.py", line 126, in _request_raw
    raise ConnectionError(CONNECTION_ERROR_MESSAGE) from None
ConnectionError: Failed to connect to Ollama. Please check that Ollama is downloaded, running and accessible. https://ollama.com/download
2025-06-30 21:36:24,043 [ERROR] Ollama attempt 3 error: Failed to connect to Ollama. Please check that Ollama is downloaded, running and accessible. https://ollama.com/download
Traceback (most recent call last):
  File "C:\Users\HP\Desktop\Ollama-Chess_GUI\grok_chess.py", line 1170, in get_ollama_move
    response = ollama.generate(
               ^^^^^^^^^^^^^^^^
  File "C:\Users\HP\anaconda3\Lib\site-packages\ollama\_client.py", line 247, in generate
    return self._request(
           ^^^^^^^^^^^^^^
  File "C:\Users\HP\anaconda3\Lib\site-packages\ollama\_client.py", line 180, in _request
    return cls(**self._request_raw(*args, **kwargs).json())
                 ^^^^^^^^^^^^^^^^^^^^^^^^^^^^^^^^^^
  File "C:\Users\HP\anaconda3\Lib\site-packages\ollama\_client.py", line 126, in _request_raw
    raise ConnectionError(CONNECTION_ERROR_MESSAGE) from None
ConnectionError: Failed to connect to Ollama. Please check that Ollama is downloaded, running and accessible. https://ollama.com/download
2025-06-30 21:36:24,044 [ERROR] Ollama failed: Ollama failed to provide valid move
Traceback (most recent call last):
  File "C:\Users\HP\Desktop\Ollama-Chess_GUI\grok_chess.py", line 1082, in get_ai_move
    raise Exception("Ollama failed to provide valid move")
Exception: Ollama failed to provide valid move
2025-06-30 21:36:24,199 [INFO] Stockfish move: c7c5
2025-06-30 21:36:24,387 [INFO] AI move took 8.50 seconds
2025-06-30 21:49:28,673 [INFO] Initializing ChessVsAI
2025-06-30 21:49:29,100 [INFO] Stockfish loaded successfully
2025-06-30 21:49:32,006 [INFO] Clicked square: e2
2025-06-30 21:49:32,007 [INFO] Selected piece: P at e2
2025-06-30 21:49:34,376 [INFO] Clicked square: e4
2025-06-30 21:49:37,222 [ERROR] Ollama attempt 1 error: Failed to connect to Ollama. Please check that Ollama is downloaded, running and accessible. https://ollama.com/download
Traceback (most recent call last):
  File "C:\Users\HP\Desktop\Ollama-Chess_GUI\grok_chess.py", line 1172, in cached_ollama_move
    response = ollama.generate(
               ^^^^^^^^^^^^^^^^
  File "C:\Users\HP\anaconda3\Lib\site-packages\ollama\_client.py", line 247, in generate
    return self._request(
           ^^^^^^^^^^^^^^
  File "C:\Users\HP\anaconda3\Lib\site-packages\ollama\_client.py", line 180, in _request
    return cls(**self._request_raw(*args, **kwargs).json())
                 ^^^^^^^^^^^^^^^^^^^^^^^^^^^^^^^^^^
  File "C:\Users\HP\anaconda3\Lib\site-packages\ollama\_client.py", line 126, in _request_raw
    raise ConnectionError(CONNECTION_ERROR_MESSAGE) from None
ConnectionError: Failed to connect to Ollama. Please check that Ollama is downloaded, running and accessible. https://ollama.com/download
2025-06-30 21:49:40,266 [ERROR] Ollama attempt 2 error: Failed to connect to Ollama. Please check that Ollama is downloaded, running and accessible. https://ollama.com/download
Traceback (most recent call last):
  File "C:\Users\HP\Desktop\Ollama-Chess_GUI\grok_chess.py", line 1172, in cached_ollama_move
    response = ollama.generate(
               ^^^^^^^^^^^^^^^^
  File "C:\Users\HP\anaconda3\Lib\site-packages\ollama\_client.py", line 247, in generate
    return self._request(
           ^^^^^^^^^^^^^^
  File "C:\Users\HP\anaconda3\Lib\site-packages\ollama\_client.py", line 180, in _request
    return cls(**self._request_raw(*args, **kwargs).json())
                 ^^^^^^^^^^^^^^^^^^^^^^^^^^^^^^^^^^
  File "C:\Users\HP\anaconda3\Lib\site-packages\ollama\_client.py", line 126, in _request_raw
    raise ConnectionError(CONNECTION_ERROR_MESSAGE) from None
ConnectionError: Failed to connect to Ollama. Please check that Ollama is downloaded, running and accessible. https://ollama.com/download
2025-06-30 21:49:44,305 [ERROR] Ollama attempt 3 error: Failed to connect to Ollama. Please check that Ollama is downloaded, running and accessible. https://ollama.com/download
Traceback (most recent call last):
  File "C:\Users\HP\Desktop\Ollama-Chess_GUI\grok_chess.py", line 1172, in cached_ollama_move
    response = ollama.generate(
               ^^^^^^^^^^^^^^^^
  File "C:\Users\HP\anaconda3\Lib\site-packages\ollama\_client.py", line 247, in generate
    return self._request(
           ^^^^^^^^^^^^^^
  File "C:\Users\HP\anaconda3\Lib\site-packages\ollama\_client.py", line 180, in _request
    return cls(**self._request_raw(*args, **kwargs).json())
                 ^^^^^^^^^^^^^^^^^^^^^^^^^^^^^^^^^^
  File "C:\Users\HP\anaconda3\Lib\site-packages\ollama\_client.py", line 126, in _request_raw
    raise ConnectionError(CONNECTION_ERROR_MESSAGE) from None
ConnectionError: Failed to connect to Ollama. Please check that Ollama is downloaded, running and accessible. https://ollama.com/download
2025-06-30 21:49:44,307 [ERROR] Ollama failed: Ollama failed to provide valid move
Traceback (most recent call last):
  File "C:\Users\HP\Desktop\Ollama-Chess_GUI\grok_chess.py", line 1301, in get_ai_move
    raise ChessError("Ollama failed to provide valid move")
ChessError: Ollama failed to provide valid move
2025-06-30 21:49:44,328 [INFO] Stockfish move: c7c5
2025-06-30 21:49:44,383 [INFO] AI move took 9.20 seconds
2025-06-30 21:49:46,579 [INFO] Clicked square: d2
2025-06-30 21:49:46,579 [INFO] Selected piece: P at d2
2025-06-30 21:49:47,988 [INFO] Clicked square: d4
2025-06-30 21:49:50,563 [ERROR] Ollama attempt 1 error: Failed to connect to Ollama. Please check that Ollama is downloaded, running and accessible. https://ollama.com/download
Traceback (most recent call last):
  File "C:\Users\HP\Desktop\Ollama-Chess_GUI\grok_chess.py", line 1172, in cached_ollama_move
    response = ollama.generate(
               ^^^^^^^^^^^^^^^^
  File "C:\Users\HP\anaconda3\Lib\site-packages\ollama\_client.py", line 247, in generate
    return self._request(
           ^^^^^^^^^^^^^^
  File "C:\Users\HP\anaconda3\Lib\site-packages\ollama\_client.py", line 180, in _request
    return cls(**self._request_raw(*args, **kwargs).json())
                 ^^^^^^^^^^^^^^^^^^^^^^^^^^^^^^^^^^
  File "C:\Users\HP\anaconda3\Lib\site-packages\ollama\_client.py", line 126, in _request_raw
    raise ConnectionError(CONNECTION_ERROR_MESSAGE) from None
ConnectionError: Failed to connect to Ollama. Please check that Ollama is downloaded, running and accessible. https://ollama.com/download
2025-06-30 21:49:53,600 [ERROR] Ollama attempt 2 error: Failed to connect to Ollama. Please check that Ollama is downloaded, running and accessible. https://ollama.com/download
Traceback (most recent call last):
  File "C:\Users\HP\Desktop\Ollama-Chess_GUI\grok_chess.py", line 1172, in cached_ollama_move
    response = ollama.generate(
               ^^^^^^^^^^^^^^^^
  File "C:\Users\HP\anaconda3\Lib\site-packages\ollama\_client.py", line 247, in generate
    return self._request(
           ^^^^^^^^^^^^^^
  File "C:\Users\HP\anaconda3\Lib\site-packages\ollama\_client.py", line 180, in _request
    return cls(**self._request_raw(*args, **kwargs).json())
                 ^^^^^^^^^^^^^^^^^^^^^^^^^^^^^^^^^^
  File "C:\Users\HP\anaconda3\Lib\site-packages\ollama\_client.py", line 126, in _request_raw
    raise ConnectionError(CONNECTION_ERROR_MESSAGE) from None
ConnectionError: Failed to connect to Ollama. Please check that Ollama is downloaded, running and accessible. https://ollama.com/download
2025-06-30 21:49:57,639 [ERROR] Ollama attempt 3 error: Failed to connect to Ollama. Please check that Ollama is downloaded, running and accessible. https://ollama.com/download
Traceback (most recent call last):
  File "C:\Users\HP\Desktop\Ollama-Chess_GUI\grok_chess.py", line 1172, in cached_ollama_move
    response = ollama.generate(
               ^^^^^^^^^^^^^^^^
  File "C:\Users\HP\anaconda3\Lib\site-packages\ollama\_client.py", line 247, in generate
    return self._request(
           ^^^^^^^^^^^^^^
  File "C:\Users\HP\anaconda3\Lib\site-packages\ollama\_client.py", line 180, in _request
    return cls(**self._request_raw(*args, **kwargs).json())
                 ^^^^^^^^^^^^^^^^^^^^^^^^^^^^^^^^^^
  File "C:\Users\HP\anaconda3\Lib\site-packages\ollama\_client.py", line 126, in _request_raw
    raise ConnectionError(CONNECTION_ERROR_MESSAGE) from None
ConnectionError: Failed to connect to Ollama. Please check that Ollama is downloaded, running and accessible. https://ollama.com/download
2025-06-30 21:49:57,641 [ERROR] Ollama failed: Ollama failed to provide valid move
Traceback (most recent call last):
  File "C:\Users\HP\Desktop\Ollama-Chess_GUI\grok_chess.py", line 1301, in get_ai_move
    raise ChessError("Ollama failed to provide valid move")
ChessError: Ollama failed to provide valid move
2025-06-30 21:49:57,662 [INFO] Stockfish move: c5d4
2025-06-30 21:49:57,698 [INFO] AI move took 9.18 seconds
2025-06-30 21:50:00,089 [INFO] Clicked square: d1
2025-06-30 21:50:00,094 [INFO] Selected piece: Q at d1
2025-06-30 21:50:01,539 [INFO] Clicked square: d4
2025-06-30 21:50:04,139 [ERROR] Ollama attempt 1 error: Failed to connect to Ollama. Please check that Ollama is downloaded, running and accessible. https://ollama.com/download
Traceback (most recent call last):
  File "C:\Users\HP\Desktop\Ollama-Chess_GUI\grok_chess.py", line 1172, in cached_ollama_move
    response = ollama.generate(
               ^^^^^^^^^^^^^^^^
  File "C:\Users\HP\anaconda3\Lib\site-packages\ollama\_client.py", line 247, in generate
    return self._request(
           ^^^^^^^^^^^^^^
  File "C:\Users\HP\anaconda3\Lib\site-packages\ollama\_client.py", line 180, in _request
    return cls(**self._request_raw(*args, **kwargs).json())
                 ^^^^^^^^^^^^^^^^^^^^^^^^^^^^^^^^^^
  File "C:\Users\HP\anaconda3\Lib\site-packages\ollama\_client.py", line 126, in _request_raw
    raise ConnectionError(CONNECTION_ERROR_MESSAGE) from None
ConnectionError: Failed to connect to Ollama. Please check that Ollama is downloaded, running and accessible. https://ollama.com/download
2025-06-30 21:50:07,191 [ERROR] Ollama attempt 2 error: Failed to connect to Ollama. Please check that Ollama is downloaded, running and accessible. https://ollama.com/download
Traceback (most recent call last):
  File "C:\Users\HP\Desktop\Ollama-Chess_GUI\grok_chess.py", line 1172, in cached_ollama_move
    response = ollama.generate(
               ^^^^^^^^^^^^^^^^
  File "C:\Users\HP\anaconda3\Lib\site-packages\ollama\_client.py", line 247, in generate
    return self._request(
           ^^^^^^^^^^^^^^
  File "C:\Users\HP\anaconda3\Lib\site-packages\ollama\_client.py", line 180, in _request
    return cls(**self._request_raw(*args, **kwargs).json())
                 ^^^^^^^^^^^^^^^^^^^^^^^^^^^^^^^^^^
  File "C:\Users\HP\anaconda3\Lib\site-packages\ollama\_client.py", line 126, in _request_raw
    raise ConnectionError(CONNECTION_ERROR_MESSAGE) from None
ConnectionError: Failed to connect to Ollama. Please check that Ollama is downloaded, running and accessible. https://ollama.com/download
2025-06-30 21:50:11,225 [ERROR] Ollama attempt 3 error: Failed to connect to Ollama. Please check that Ollama is downloaded, running and accessible. https://ollama.com/download
Traceback (most recent call last):
  File "C:\Users\HP\Desktop\Ollama-Chess_GUI\grok_chess.py", line 1172, in cached_ollama_move
    response = ollama.generate(
               ^^^^^^^^^^^^^^^^
  File "C:\Users\HP\anaconda3\Lib\site-packages\ollama\_client.py", line 247, in generate
    return self._request(
           ^^^^^^^^^^^^^^
  File "C:\Users\HP\anaconda3\Lib\site-packages\ollama\_client.py", line 180, in _request
    return cls(**self._request_raw(*args, **kwargs).json())
                 ^^^^^^^^^^^^^^^^^^^^^^^^^^^^^^^^^^
  File "C:\Users\HP\anaconda3\Lib\site-packages\ollama\_client.py", line 126, in _request_raw
    raise ConnectionError(CONNECTION_ERROR_MESSAGE) from None
ConnectionError: Failed to connect to Ollama. Please check that Ollama is downloaded, running and accessible. https://ollama.com/download
2025-06-30 21:50:11,227 [ERROR] Ollama failed: Ollama failed to provide valid move
Traceback (most recent call last):
  File "C:\Users\HP\Desktop\Ollama-Chess_GUI\grok_chess.py", line 1301, in get_ai_move
    raise ChessError("Ollama failed to provide valid move")
ChessError: Ollama failed to provide valid move
2025-06-30 21:50:11,236 [INFO] Stockfish move: b8c6
2025-06-30 21:50:11,274 [INFO] AI move took 9.18 seconds
2025-06-30 21:50:18,102 [ERROR] Failed to auto-save PGN: module 'chess' has no attribute 'pgn'
Traceback (most recent call last):
  File "C:\Users\HP\Desktop\Ollama-Chess_GUI\grok_chess.py", line 561, in auto_save_pgn
    game = self.create_pgn_game()
           ^^^^^^^^^^^^^^^^^^^^^^
  File "C:\Users\HP\Desktop\Ollama-Chess_GUI\grok_chess.py", line 576, in create_pgn_game
    game = chess.pgn.Game()
           ^^^^^^^^^
AttributeError: module 'chess' has no attribute 'pgn'
2025-06-30 21:50:47,198 [ERROR] On closing error: engine event loop dead
Traceback (most recent call last):
  File "C:\Users\HP\Desktop\Ollama-Chess_GUI\grok_chess.py", line 411, in on_closing
    self.engine.quit()
  File "C:\Users\HP\anaconda3\Lib\site-packages\chess\engine.py", line 3011, in quit
    with self._not_shut_down():
         ^^^^^^^^^^^^^^^^^^^^^
  File "C:\Users\HP\anaconda3\Lib\contextlib.py", line 137, in __enter__
    return next(self.gen)
           ^^^^^^^^^^^^^^
  File "C:\Users\HP\anaconda3\Lib\site-packages\chess\engine.py", line 2931, in _not_shut_down
    raise EngineTerminatedError("engine event loop dead")
chess.engine.EngineTerminatedError: engine event loop dead
2025-06-30 22:00:24,500 [INFO] Initializing ChessVsAI
2025-06-30 22:00:24,951 [INFO] Stockfish loaded successfully
2025-06-30 22:00:29,520 [INFO] Clicked square: e2
2025-06-30 22:00:29,521 [INFO] Selected piece: P at e2
2025-06-30 22:00:30,899 [INFO] Clicked square: e4
2025-06-30 22:00:33,762 [ERROR] Ollama attempt 1 error: Failed to connect to Ollama. Please check that Ollama is downloaded, running and accessible. https://ollama.com/download
Traceback (most recent call last):
  File "C:\Users\HP\Desktop\Ollama-Chess_GUI\grok_chess.py", line 1172, in cached_ollama_move
    response = ollama.generate(
               ^^^^^^^^^^^^^^^^
  File "C:\Users\HP\anaconda3\Lib\site-packages\ollama\_client.py", line 247, in generate
    return self._request(
           ^^^^^^^^^^^^^^
  File "C:\Users\HP\anaconda3\Lib\site-packages\ollama\_client.py", line 180, in _request
    return cls(**self._request_raw(*args, **kwargs).json())
                 ^^^^^^^^^^^^^^^^^^^^^^^^^^^^^^^^^^
  File "C:\Users\HP\anaconda3\Lib\site-packages\ollama\_client.py", line 126, in _request_raw
    raise ConnectionError(CONNECTION_ERROR_MESSAGE) from None
ConnectionError: Failed to connect to Ollama. Please check that Ollama is downloaded, running and accessible. https://ollama.com/download
2025-06-30 22:00:36,785 [ERROR] Ollama attempt 2 error: Failed to connect to Ollama. Please check that Ollama is downloaded, running and accessible. https://ollama.com/download
Traceback (most recent call last):
  File "C:\Users\HP\Desktop\Ollama-Chess_GUI\grok_chess.py", line 1172, in cached_ollama_move
    response = ollama.generate(
               ^^^^^^^^^^^^^^^^
  File "C:\Users\HP\anaconda3\Lib\site-packages\ollama\_client.py", line 247, in generate
    return self._request(
           ^^^^^^^^^^^^^^
  File "C:\Users\HP\anaconda3\Lib\site-packages\ollama\_client.py", line 180, in _request
    return cls(**self._request_raw(*args, **kwargs).json())
                 ^^^^^^^^^^^^^^^^^^^^^^^^^^^^^^^^^^
  File "C:\Users\HP\anaconda3\Lib\site-packages\ollama\_client.py", line 126, in _request_raw
    raise ConnectionError(CONNECTION_ERROR_MESSAGE) from None
ConnectionError: Failed to connect to Ollama. Please check that Ollama is downloaded, running and accessible. https://ollama.com/download
2025-06-30 22:00:40,825 [ERROR] Ollama attempt 3 error: Failed to connect to Ollama. Please check that Ollama is downloaded, running and accessible. https://ollama.com/download
Traceback (most recent call last):
  File "C:\Users\HP\Desktop\Ollama-Chess_GUI\grok_chess.py", line 1172, in cached_ollama_move
    response = ollama.generate(
               ^^^^^^^^^^^^^^^^
  File "C:\Users\HP\anaconda3\Lib\site-packages\ollama\_client.py", line 247, in generate
    return self._request(
           ^^^^^^^^^^^^^^
  File "C:\Users\HP\anaconda3\Lib\site-packages\ollama\_client.py", line 180, in _request
    return cls(**self._request_raw(*args, **kwargs).json())
                 ^^^^^^^^^^^^^^^^^^^^^^^^^^^^^^^^^^
  File "C:\Users\HP\anaconda3\Lib\site-packages\ollama\_client.py", line 126, in _request_raw
    raise ConnectionError(CONNECTION_ERROR_MESSAGE) from None
ConnectionError: Failed to connect to Ollama. Please check that Ollama is downloaded, running and accessible. https://ollama.com/download
2025-06-30 22:00:40,827 [ERROR] Ollama failed: Ollama failed to provide valid move
Traceback (most recent call last):
  File "C:\Users\HP\Desktop\Ollama-Chess_GUI\grok_chess.py", line 1301, in get_ai_move
    raise ChessError("Ollama failed to provide valid move")
ChessError: Ollama failed to provide valid move
2025-06-30 22:00:40,834 [INFO] Stockfish move: e7e5
2025-06-30 22:00:40,873 [INFO] AI move took 9.14 seconds
2025-06-30 22:00:42,515 [INFO] Clicked square: g1
2025-06-30 22:00:42,518 [INFO] Selected piece: N at g1
2025-06-30 22:00:43,890 [INFO] Clicked square: f3
2025-06-30 22:00:46,496 [ERROR] Ollama attempt 1 error: Failed to connect to Ollama. Please check that Ollama is downloaded, running and accessible. https://ollama.com/download
Traceback (most recent call last):
  File "C:\Users\HP\Desktop\Ollama-Chess_GUI\grok_chess.py", line 1172, in cached_ollama_move
    response = ollama.generate(
               ^^^^^^^^^^^^^^^^
  File "C:\Users\HP\anaconda3\Lib\site-packages\ollama\_client.py", line 247, in generate
    return self._request(
           ^^^^^^^^^^^^^^
  File "C:\Users\HP\anaconda3\Lib\site-packages\ollama\_client.py", line 180, in _request
    return cls(**self._request_raw(*args, **kwargs).json())
                 ^^^^^^^^^^^^^^^^^^^^^^^^^^^^^^^^^^
  File "C:\Users\HP\anaconda3\Lib\site-packages\ollama\_client.py", line 126, in _request_raw
    raise ConnectionError(CONNECTION_ERROR_MESSAGE) from None
ConnectionError: Failed to connect to Ollama. Please check that Ollama is downloaded, running and accessible. https://ollama.com/download
2025-06-30 22:00:49,524 [ERROR] Ollama attempt 2 error: Failed to connect to Ollama. Please check that Ollama is downloaded, running and accessible. https://ollama.com/download
Traceback (most recent call last):
  File "C:\Users\HP\Desktop\Ollama-Chess_GUI\grok_chess.py", line 1172, in cached_ollama_move
    response = ollama.generate(
               ^^^^^^^^^^^^^^^^
  File "C:\Users\HP\anaconda3\Lib\site-packages\ollama\_client.py", line 247, in generate
    return self._request(
           ^^^^^^^^^^^^^^
  File "C:\Users\HP\anaconda3\Lib\site-packages\ollama\_client.py", line 180, in _request
    return cls(**self._request_raw(*args, **kwargs).json())
                 ^^^^^^^^^^^^^^^^^^^^^^^^^^^^^^^^^^
  File "C:\Users\HP\anaconda3\Lib\site-packages\ollama\_client.py", line 126, in _request_raw
    raise ConnectionError(CONNECTION_ERROR_MESSAGE) from None
ConnectionError: Failed to connect to Ollama. Please check that Ollama is downloaded, running and accessible. https://ollama.com/download
2025-06-30 22:00:53,542 [ERROR] Ollama attempt 3 error: Failed to connect to Ollama. Please check that Ollama is downloaded, running and accessible. https://ollama.com/download
Traceback (most recent call last):
  File "C:\Users\HP\Desktop\Ollama-Chess_GUI\grok_chess.py", line 1172, in cached_ollama_move
    response = ollama.generate(
               ^^^^^^^^^^^^^^^^
  File "C:\Users\HP\anaconda3\Lib\site-packages\ollama\_client.py", line 247, in generate
    return self._request(
           ^^^^^^^^^^^^^^
  File "C:\Users\HP\anaconda3\Lib\site-packages\ollama\_client.py", line 180, in _request
    return cls(**self._request_raw(*args, **kwargs).json())
                 ^^^^^^^^^^^^^^^^^^^^^^^^^^^^^^^^^^
  File "C:\Users\HP\anaconda3\Lib\site-packages\ollama\_client.py", line 126, in _request_raw
    raise ConnectionError(CONNECTION_ERROR_MESSAGE) from None
ConnectionError: Failed to connect to Ollama. Please check that Ollama is downloaded, running and accessible. https://ollama.com/download
2025-06-30 22:00:53,544 [ERROR] Ollama failed: Ollama failed to provide valid move
Traceback (most recent call last):
  File "C:\Users\HP\Desktop\Ollama-Chess_GUI\grok_chess.py", line 1301, in get_ai_move
    raise ChessError("Ollama failed to provide valid move")
ChessError: Ollama failed to provide valid move
2025-06-30 22:00:53,556 [INFO] Stockfish move: b8c6
2025-06-30 22:00:53,590 [INFO] AI move took 9.13 seconds
2025-06-30 22:00:55,710 [INFO] Clicked square: f1
2025-06-30 22:00:55,712 [INFO] Selected piece: B at f1
2025-06-30 22:00:57,275 [INFO] Clicked square: b5
2025-06-30 22:00:59,876 [ERROR] Ollama attempt 1 error: Failed to connect to Ollama. Please check that Ollama is downloaded, running and accessible. https://ollama.com/download
Traceback (most recent call last):
  File "C:\Users\HP\Desktop\Ollama-Chess_GUI\grok_chess.py", line 1172, in cached_ollama_move
    response = ollama.generate(
               ^^^^^^^^^^^^^^^^
  File "C:\Users\HP\anaconda3\Lib\site-packages\ollama\_client.py", line 247, in generate
    return self._request(
           ^^^^^^^^^^^^^^
  File "C:\Users\HP\anaconda3\Lib\site-packages\ollama\_client.py", line 180, in _request
    return cls(**self._request_raw(*args, **kwargs).json())
                 ^^^^^^^^^^^^^^^^^^^^^^^^^^^^^^^^^^
  File "C:\Users\HP\anaconda3\Lib\site-packages\ollama\_client.py", line 126, in _request_raw
    raise ConnectionError(CONNECTION_ERROR_MESSAGE) from None
ConnectionError: Failed to connect to Ollama. Please check that Ollama is downloaded, running and accessible. https://ollama.com/download
2025-06-30 22:01:02,909 [ERROR] Ollama attempt 2 error: Failed to connect to Ollama. Please check that Ollama is downloaded, running and accessible. https://ollama.com/download
Traceback (most recent call last):
  File "C:\Users\HP\Desktop\Ollama-Chess_GUI\grok_chess.py", line 1172, in cached_ollama_move
    response = ollama.generate(
               ^^^^^^^^^^^^^^^^
  File "C:\Users\HP\anaconda3\Lib\site-packages\ollama\_client.py", line 247, in generate
    return self._request(
           ^^^^^^^^^^^^^^
  File "C:\Users\HP\anaconda3\Lib\site-packages\ollama\_client.py", line 180, in _request
    return cls(**self._request_raw(*args, **kwargs).json())
                 ^^^^^^^^^^^^^^^^^^^^^^^^^^^^^^^^^^
  File "C:\Users\HP\anaconda3\Lib\site-packages\ollama\_client.py", line 126, in _request_raw
    raise ConnectionError(CONNECTION_ERROR_MESSAGE) from None
ConnectionError: Failed to connect to Ollama. Please check that Ollama is downloaded, running and accessible. https://ollama.com/download
2025-06-30 22:01:06,940 [ERROR] Ollama attempt 3 error: Failed to connect to Ollama. Please check that Ollama is downloaded, running and accessible. https://ollama.com/download
Traceback (most recent call last):
  File "C:\Users\HP\Desktop\Ollama-Chess_GUI\grok_chess.py", line 1172, in cached_ollama_move
    response = ollama.generate(
               ^^^^^^^^^^^^^^^^
  File "C:\Users\HP\anaconda3\Lib\site-packages\ollama\_client.py", line 247, in generate
    return self._request(
           ^^^^^^^^^^^^^^
  File "C:\Users\HP\anaconda3\Lib\site-packages\ollama\_client.py", line 180, in _request
    return cls(**self._request_raw(*args, **kwargs).json())
                 ^^^^^^^^^^^^^^^^^^^^^^^^^^^^^^^^^^
  File "C:\Users\HP\anaconda3\Lib\site-packages\ollama\_client.py", line 126, in _request_raw
    raise ConnectionError(CONNECTION_ERROR_MESSAGE) from None
ConnectionError: Failed to connect to Ollama. Please check that Ollama is downloaded, running and accessible. https://ollama.com/download
2025-06-30 22:01:06,941 [ERROR] Ollama failed: Ollama failed to provide valid move
Traceback (most recent call last):
  File "C:\Users\HP\Desktop\Ollama-Chess_GUI\grok_chess.py", line 1301, in get_ai_move
    raise ChessError("Ollama failed to provide valid move")
ChessError: Ollama failed to provide valid move
2025-06-30 22:01:06,963 [INFO] Stockfish move: a7a6
2025-06-30 22:01:06,999 [INFO] AI move took 9.17 seconds
2025-06-30 22:01:10,015 [ERROR] Failed to auto-save PGN: module 'chess' has no attribute 'pgn'
Traceback (most recent call last):
  File "C:\Users\HP\Desktop\Ollama-Chess_GUI\grok_chess.py", line 561, in auto_save_pgn
    game = self.create_pgn_game()
           ^^^^^^^^^^^^^^^^^^^^^^
  File "C:\Users\HP\Desktop\Ollama-Chess_GUI\grok_chess.py", line 576, in create_pgn_game
    game = chess.pgn.Game()
           ^^^^^^^^^
AttributeError: module 'chess' has no attribute 'pgn'
2025-07-01 06:11:38,203 [INFO] Initializing ChessVsAI
2025-07-01 06:11:38,726 [INFO] Stockfish loaded successfully
2025-07-01 06:11:43,733 [INFO] Clicked square: e2
2025-07-01 06:11:43,733 [INFO] Selected piece: P at e2
2025-07-01 06:11:45,319 [INFO] Clicked square: e4
2025-07-01 06:11:48,279 [ERROR] Ollama attempt 1 error: Failed to connect to Ollama. Please check that Ollama is downloaded, running and accessible. https://ollama.com/download
Traceback (most recent call last):
  File "C:\Users\HP\Desktop\Ollama-Chess_GUI\grok_chess.py", line 1172, in cached_ollama_move
    response = ollama.generate(
               ^^^^^^^^^^^^^^^^
  File "C:\Users\HP\anaconda3\Lib\site-packages\ollama\_client.py", line 247, in generate
    return self._request(
           ^^^^^^^^^^^^^^
  File "C:\Users\HP\anaconda3\Lib\site-packages\ollama\_client.py", line 180, in _request
    return cls(**self._request_raw(*args, **kwargs).json())
                 ^^^^^^^^^^^^^^^^^^^^^^^^^^^^^^^^^^
  File "C:\Users\HP\anaconda3\Lib\site-packages\ollama\_client.py", line 126, in _request_raw
    raise ConnectionError(CONNECTION_ERROR_MESSAGE) from None
ConnectionError: Failed to connect to Ollama. Please check that Ollama is downloaded, running and accessible. https://ollama.com/download
2025-07-01 06:11:51,356 [ERROR] Ollama attempt 2 error: Failed to connect to Ollama. Please check that Ollama is downloaded, running and accessible. https://ollama.com/download
Traceback (most recent call last):
  File "C:\Users\HP\Desktop\Ollama-Chess_GUI\grok_chess.py", line 1172, in cached_ollama_move
    response = ollama.generate(
               ^^^^^^^^^^^^^^^^
  File "C:\Users\HP\anaconda3\Lib\site-packages\ollama\_client.py", line 247, in generate
    return self._request(
           ^^^^^^^^^^^^^^
  File "C:\Users\HP\anaconda3\Lib\site-packages\ollama\_client.py", line 180, in _request
    return cls(**self._request_raw(*args, **kwargs).json())
                 ^^^^^^^^^^^^^^^^^^^^^^^^^^^^^^^^^^
  File "C:\Users\HP\anaconda3\Lib\site-packages\ollama\_client.py", line 126, in _request_raw
    raise ConnectionError(CONNECTION_ERROR_MESSAGE) from None
ConnectionError: Failed to connect to Ollama. Please check that Ollama is downloaded, running and accessible. https://ollama.com/download
2025-07-01 06:11:55,371 [ERROR] Ollama attempt 3 error: Failed to connect to Ollama. Please check that Ollama is downloaded, running and accessible. https://ollama.com/download
Traceback (most recent call last):
  File "C:\Users\HP\Desktop\Ollama-Chess_GUI\grok_chess.py", line 1172, in cached_ollama_move
    response = ollama.generate(
               ^^^^^^^^^^^^^^^^
  File "C:\Users\HP\anaconda3\Lib\site-packages\ollama\_client.py", line 247, in generate
    return self._request(
           ^^^^^^^^^^^^^^
  File "C:\Users\HP\anaconda3\Lib\site-packages\ollama\_client.py", line 180, in _request
    return cls(**self._request_raw(*args, **kwargs).json())
                 ^^^^^^^^^^^^^^^^^^^^^^^^^^^^^^^^^^
  File "C:\Users\HP\anaconda3\Lib\site-packages\ollama\_client.py", line 126, in _request_raw
    raise ConnectionError(CONNECTION_ERROR_MESSAGE) from None
ConnectionError: Failed to connect to Ollama. Please check that Ollama is downloaded, running and accessible. https://ollama.com/download
2025-07-01 06:11:55,375 [ERROR] Ollama failed: Ollama failed to provide valid move
Traceback (most recent call last):
  File "C:\Users\HP\Desktop\Ollama-Chess_GUI\grok_chess.py", line 1301, in get_ai_move
    raise ChessError("Ollama failed to provide valid move")
ChessError: Ollama failed to provide valid move
2025-07-01 06:11:55,385 [INFO] Stockfish move: e7e5
2025-07-01 06:11:55,419 [INFO] AI move took 9.19 seconds
2025-07-01 06:11:57,885 [INFO] Clicked square: g1
2025-07-01 06:11:57,885 [INFO] Selected piece: N at g1
2025-07-01 06:11:59,109 [INFO] Clicked square: f3
2025-07-01 06:12:01,706 [ERROR] Ollama attempt 1 error: Failed to connect to Ollama. Please check that Ollama is downloaded, running and accessible. https://ollama.com/download
Traceback (most recent call last):
  File "C:\Users\HP\Desktop\Ollama-Chess_GUI\grok_chess.py", line 1172, in cached_ollama_move
    response = ollama.generate(
               ^^^^^^^^^^^^^^^^
  File "C:\Users\HP\anaconda3\Lib\site-packages\ollama\_client.py", line 247, in generate
    return self._request(
           ^^^^^^^^^^^^^^
  File "C:\Users\HP\anaconda3\Lib\site-packages\ollama\_client.py", line 180, in _request
    return cls(**self._request_raw(*args, **kwargs).json())
                 ^^^^^^^^^^^^^^^^^^^^^^^^^^^^^^^^^^
  File "C:\Users\HP\anaconda3\Lib\site-packages\ollama\_client.py", line 126, in _request_raw
    raise ConnectionError(CONNECTION_ERROR_MESSAGE) from None
ConnectionError: Failed to connect to Ollama. Please check that Ollama is downloaded, running and accessible. https://ollama.com/download
2025-07-01 06:12:04,733 [ERROR] Ollama attempt 2 error: Failed to connect to Ollama. Please check that Ollama is downloaded, running and accessible. https://ollama.com/download
Traceback (most recent call last):
  File "C:\Users\HP\Desktop\Ollama-Chess_GUI\grok_chess.py", line 1172, in cached_ollama_move
    response = ollama.generate(
               ^^^^^^^^^^^^^^^^
  File "C:\Users\HP\anaconda3\Lib\site-packages\ollama\_client.py", line 247, in generate
    return self._request(
           ^^^^^^^^^^^^^^
  File "C:\Users\HP\anaconda3\Lib\site-packages\ollama\_client.py", line 180, in _request
    return cls(**self._request_raw(*args, **kwargs).json())
                 ^^^^^^^^^^^^^^^^^^^^^^^^^^^^^^^^^^
  File "C:\Users\HP\anaconda3\Lib\site-packages\ollama\_client.py", line 126, in _request_raw
    raise ConnectionError(CONNECTION_ERROR_MESSAGE) from None
ConnectionError: Failed to connect to Ollama. Please check that Ollama is downloaded, running and accessible. https://ollama.com/download
2025-07-01 06:12:08,759 [ERROR] Ollama attempt 3 error: Failed to connect to Ollama. Please check that Ollama is downloaded, running and accessible. https://ollama.com/download
Traceback (most recent call last):
  File "C:\Users\HP\Desktop\Ollama-Chess_GUI\grok_chess.py", line 1172, in cached_ollama_move
    response = ollama.generate(
               ^^^^^^^^^^^^^^^^
  File "C:\Users\HP\anaconda3\Lib\site-packages\ollama\_client.py", line 247, in generate
    return self._request(
           ^^^^^^^^^^^^^^
  File "C:\Users\HP\anaconda3\Lib\site-packages\ollama\_client.py", line 180, in _request
    return cls(**self._request_raw(*args, **kwargs).json())
                 ^^^^^^^^^^^^^^^^^^^^^^^^^^^^^^^^^^
  File "C:\Users\HP\anaconda3\Lib\site-packages\ollama\_client.py", line 126, in _request_raw
    raise ConnectionError(CONNECTION_ERROR_MESSAGE) from None
ConnectionError: Failed to connect to Ollama. Please check that Ollama is downloaded, running and accessible. https://ollama.com/download
2025-07-01 06:12:08,761 [ERROR] Ollama failed: Ollama failed to provide valid move
Traceback (most recent call last):
  File "C:\Users\HP\Desktop\Ollama-Chess_GUI\grok_chess.py", line 1301, in get_ai_move
    raise ChessError("Ollama failed to provide valid move")
ChessError: Ollama failed to provide valid move
2025-07-01 06:12:08,770 [INFO] Stockfish move: b8c6
2025-07-01 06:12:08,818 [INFO] AI move took 9.16 seconds
2025-07-01 06:12:10,794 [ERROR] Failed to auto-save PGN: module 'chess' has no attribute 'pgn'
Traceback (most recent call last):
  File "C:\Users\HP\Desktop\Ollama-Chess_GUI\grok_chess.py", line 561, in auto_save_pgn
    game = self.create_pgn_game()
           ^^^^^^^^^^^^^^^^^^^^^^
  File "C:\Users\HP\Desktop\Ollama-Chess_GUI\grok_chess.py", line 576, in create_pgn_game
    game = chess.pgn.Game()
           ^^^^^^^^^
AttributeError: module 'chess' has no attribute 'pgn'
2025-07-01 06:30:53,481 [ERROR] On closing error: engine event loop dead
Traceback (most recent call last):
  File "C:\Users\HP\Desktop\Ollama-Chess_GUI\grok_chess.py", line 411, in on_closing
    self.engine.quit()
  File "C:\Users\HP\anaconda3\Lib\site-packages\chess\engine.py", line 3011, in quit
    with self._not_shut_down():
         ^^^^^^^^^^^^^^^^^^^^^
  File "C:\Users\HP\anaconda3\Lib\contextlib.py", line 137, in __enter__
    return next(self.gen)
           ^^^^^^^^^^^^^^
  File "C:\Users\HP\anaconda3\Lib\site-packages\chess\engine.py", line 2931, in _not_shut_down
    raise EngineTerminatedError("engine event loop dead")
chess.engine.EngineTerminatedError: engine event loop dead
2025-07-01 06:31:00,801 [INFO] Initializing ChessVsAI
2025-07-01 06:31:01,232 [INFO] Stockfish loaded successfully
2025-07-01 06:31:10,898 [INFO] Clicked square: e2
2025-07-01 06:31:10,898 [INFO] Selected piece: P at e2
2025-07-01 06:31:12,279 [INFO] Clicked square: e4
2025-07-01 06:31:15,137 [ERROR] Ollama attempt 1 error: Failed to connect to Ollama. Please check that Ollama is downloaded, running and accessible. https://ollama.com/download
Traceback (most recent call last):
  File "C:\Users\HP\Desktop\Ollama-Chess_GUI\grok_chess.py", line 1172, in cached_ollama_move
    response = ollama.generate(
               ^^^^^^^^^^^^^^^^
  File "C:\Users\HP\anaconda3\Lib\site-packages\ollama\_client.py", line 247, in generate
    return self._request(
           ^^^^^^^^^^^^^^
  File "C:\Users\HP\anaconda3\Lib\site-packages\ollama\_client.py", line 180, in _request
    return cls(**self._request_raw(*args, **kwargs).json())
                 ^^^^^^^^^^^^^^^^^^^^^^^^^^^^^^^^^^
  File "C:\Users\HP\anaconda3\Lib\site-packages\ollama\_client.py", line 126, in _request_raw
    raise ConnectionError(CONNECTION_ERROR_MESSAGE) from None
ConnectionError: Failed to connect to Ollama. Please check that Ollama is downloaded, running and accessible. https://ollama.com/download
2025-07-01 06:31:18,173 [ERROR] Ollama attempt 2 error: Failed to connect to Ollama. Please check that Ollama is downloaded, running and accessible. https://ollama.com/download
Traceback (most recent call last):
  File "C:\Users\HP\Desktop\Ollama-Chess_GUI\grok_chess.py", line 1172, in cached_ollama_move
    response = ollama.generate(
               ^^^^^^^^^^^^^^^^
  File "C:\Users\HP\anaconda3\Lib\site-packages\ollama\_client.py", line 247, in generate
    return self._request(
           ^^^^^^^^^^^^^^
  File "C:\Users\HP\anaconda3\Lib\site-packages\ollama\_client.py", line 180, in _request
    return cls(**self._request_raw(*args, **kwargs).json())
                 ^^^^^^^^^^^^^^^^^^^^^^^^^^^^^^^^^^
  File "C:\Users\HP\anaconda3\Lib\site-packages\ollama\_client.py", line 126, in _request_raw
    raise ConnectionError(CONNECTION_ERROR_MESSAGE) from None
ConnectionError: Failed to connect to Ollama. Please check that Ollama is downloaded, running and accessible. https://ollama.com/download
2025-07-01 06:31:22,209 [ERROR] Ollama attempt 3 error: Failed to connect to Ollama. Please check that Ollama is downloaded, running and accessible. https://ollama.com/download
Traceback (most recent call last):
  File "C:\Users\HP\Desktop\Ollama-Chess_GUI\grok_chess.py", line 1172, in cached_ollama_move
    response = ollama.generate(
               ^^^^^^^^^^^^^^^^
  File "C:\Users\HP\anaconda3\Lib\site-packages\ollama\_client.py", line 247, in generate
    return self._request(
           ^^^^^^^^^^^^^^
  File "C:\Users\HP\anaconda3\Lib\site-packages\ollama\_client.py", line 180, in _request
    return cls(**self._request_raw(*args, **kwargs).json())
                 ^^^^^^^^^^^^^^^^^^^^^^^^^^^^^^^^^^
  File "C:\Users\HP\anaconda3\Lib\site-packages\ollama\_client.py", line 126, in _request_raw
    raise ConnectionError(CONNECTION_ERROR_MESSAGE) from None
ConnectionError: Failed to connect to Ollama. Please check that Ollama is downloaded, running and accessible. https://ollama.com/download
2025-07-01 06:31:22,211 [ERROR] Ollama failed: Ollama failed to provide valid move
Traceback (most recent call last):
  File "C:\Users\HP\Desktop\Ollama-Chess_GUI\grok_chess.py", line 1301, in get_ai_move
    raise ChessError("Ollama failed to provide valid move")
ChessError: Ollama failed to provide valid move
2025-07-01 06:31:22,218 [INFO] Stockfish move: e7e5
2025-07-01 06:31:22,258 [INFO] AI move took 9.16 seconds
2025-07-01 06:35:13,772 [ERROR] On closing error: engine event loop dead
Traceback (most recent call last):
  File "C:\Users\HP\Desktop\Ollama-Chess_GUI\grok_chess.py", line 411, in on_closing
    self.engine.quit()
  File "C:\Users\HP\anaconda3\Lib\site-packages\chess\engine.py", line 3011, in quit
    with self._not_shut_down():
         ^^^^^^^^^^^^^^^^^^^^^
  File "C:\Users\HP\anaconda3\Lib\contextlib.py", line 137, in __enter__
    return next(self.gen)
           ^^^^^^^^^^^^^^
  File "C:\Users\HP\anaconda3\Lib\site-packages\chess\engine.py", line 2931, in _not_shut_down
    raise EngineTerminatedError("engine event loop dead")
chess.engine.EngineTerminatedError: engine event loop dead
2025-07-11 22:30:22,582 [INFO] Initializing ChessVsAI
2025-07-11 22:30:23,562 [INFO] Stockfish loaded successfully
2025-07-11 22:30:27,875 [INFO] AI difficulty set to easy
2025-07-11 22:30:30,258 [INFO] Clicked square: e2
2025-07-11 22:30:30,258 [INFO] Selected piece: P at e2
2025-07-11 22:30:31,597 [INFO] Clicked square: e4
2025-07-11 22:30:34,345 [ERROR] Ollama attempt 1 error: Failed to connect to Ollama. Please check that Ollama is downloaded, running and accessible. https://ollama.com/download
Traceback (most recent call last):
  File "C:\Users\HP\Desktop\Ollama-Chess_GUI\grok_chess.py", line 1353, in cached_ollama_move
    response = ollama.generate(
               ^^^^^^^^^^^^^^^^
  File "C:\Users\HP\anaconda3\Lib\site-packages\ollama\_client.py", line 247, in generate
    return self._request(
           ^^^^^^^^^^^^^^
  File "C:\Users\HP\anaconda3\Lib\site-packages\ollama\_client.py", line 180, in _request
    return cls(**self._request_raw(*args, **kwargs).json())
                 ^^^^^^^^^^^^^^^^^^^^^^^^^^^^^^^^^^
  File "C:\Users\HP\anaconda3\Lib\site-packages\ollama\_client.py", line 126, in _request_raw
    raise ConnectionError(CONNECTION_ERROR_MESSAGE) from None
ConnectionError: Failed to connect to Ollama. Please check that Ollama is downloaded, running and accessible. https://ollama.com/download
2025-07-11 22:30:37,384 [ERROR] Ollama attempt 2 error: Failed to connect to Ollama. Please check that Ollama is downloaded, running and accessible. https://ollama.com/download
Traceback (most recent call last):
  File "C:\Users\HP\Desktop\Ollama-Chess_GUI\grok_chess.py", line 1353, in cached_ollama_move
    response = ollama.generate(
               ^^^^^^^^^^^^^^^^
  File "C:\Users\HP\anaconda3\Lib\site-packages\ollama\_client.py", line 247, in generate
    return self._request(
           ^^^^^^^^^^^^^^
  File "C:\Users\HP\anaconda3\Lib\site-packages\ollama\_client.py", line 180, in _request
    return cls(**self._request_raw(*args, **kwargs).json())
                 ^^^^^^^^^^^^^^^^^^^^^^^^^^^^^^^^^^
  File "C:\Users\HP\anaconda3\Lib\site-packages\ollama\_client.py", line 126, in _request_raw
    raise ConnectionError(CONNECTION_ERROR_MESSAGE) from None
ConnectionError: Failed to connect to Ollama. Please check that Ollama is downloaded, running and accessible. https://ollama.com/download
2025-07-11 22:30:41,416 [ERROR] Ollama attempt 3 error: Failed to connect to Ollama. Please check that Ollama is downloaded, running and accessible. https://ollama.com/download
Traceback (most recent call last):
  File "C:\Users\HP\Desktop\Ollama-Chess_GUI\grok_chess.py", line 1353, in cached_ollama_move
    response = ollama.generate(
               ^^^^^^^^^^^^^^^^
  File "C:\Users\HP\anaconda3\Lib\site-packages\ollama\_client.py", line 247, in generate
    return self._request(
           ^^^^^^^^^^^^^^
  File "C:\Users\HP\anaconda3\Lib\site-packages\ollama\_client.py", line 180, in _request
    return cls(**self._request_raw(*args, **kwargs).json())
                 ^^^^^^^^^^^^^^^^^^^^^^^^^^^^^^^^^^
  File "C:\Users\HP\anaconda3\Lib\site-packages\ollama\_client.py", line 126, in _request_raw
    raise ConnectionError(CONNECTION_ERROR_MESSAGE) from None
ConnectionError: Failed to connect to Ollama. Please check that Ollama is downloaded, running and accessible. https://ollama.com/download
2025-07-11 22:30:41,417 [ERROR] Ollama failed: Ollama failed to provide valid move
Traceback (most recent call last):
  File "C:\Users\HP\Desktop\Ollama-Chess_GUI\grok_chess.py", line 1497, in get_ai_move
    raise ChessError("Ollama failed to provide valid move")
ChessError: Ollama failed to provide valid move
2025-07-11 22:30:41,419 [INFO] Stockfish move: e7e5
2025-07-11 22:30:41,429 [INFO] AI move took 9.11 seconds
2025-07-11 22:30:49,524 [INFO] Clicked square: g1
2025-07-11 22:30:49,524 [INFO] Selected piece: N at g1
2025-07-11 22:30:50,378 [INFO] Clicked square: f3
2025-07-11 22:30:52,935 [ERROR] Ollama attempt 1 error: Failed to connect to Ollama. Please check that Ollama is downloaded, running and accessible. https://ollama.com/download
Traceback (most recent call last):
  File "C:\Users\HP\Desktop\Ollama-Chess_GUI\grok_chess.py", line 1353, in cached_ollama_move
    response = ollama.generate(
               ^^^^^^^^^^^^^^^^
  File "C:\Users\HP\anaconda3\Lib\site-packages\ollama\_client.py", line 247, in generate
    return self._request(
           ^^^^^^^^^^^^^^
  File "C:\Users\HP\anaconda3\Lib\site-packages\ollama\_client.py", line 180, in _request
    return cls(**self._request_raw(*args, **kwargs).json())
                 ^^^^^^^^^^^^^^^^^^^^^^^^^^^^^^^^^^
  File "C:\Users\HP\anaconda3\Lib\site-packages\ollama\_client.py", line 126, in _request_raw
    raise ConnectionError(CONNECTION_ERROR_MESSAGE) from None
ConnectionError: Failed to connect to Ollama. Please check that Ollama is downloaded, running and accessible. https://ollama.com/download
2025-07-11 22:30:55,966 [ERROR] Ollama attempt 2 error: Failed to connect to Ollama. Please check that Ollama is downloaded, running and accessible. https://ollama.com/download
Traceback (most recent call last):
  File "C:\Users\HP\Desktop\Ollama-Chess_GUI\grok_chess.py", line 1353, in cached_ollama_move
    response = ollama.generate(
               ^^^^^^^^^^^^^^^^
  File "C:\Users\HP\anaconda3\Lib\site-packages\ollama\_client.py", line 247, in generate
    return self._request(
           ^^^^^^^^^^^^^^
  File "C:\Users\HP\anaconda3\Lib\site-packages\ollama\_client.py", line 180, in _request
    return cls(**self._request_raw(*args, **kwargs).json())
                 ^^^^^^^^^^^^^^^^^^^^^^^^^^^^^^^^^^
  File "C:\Users\HP\anaconda3\Lib\site-packages\ollama\_client.py", line 126, in _request_raw
    raise ConnectionError(CONNECTION_ERROR_MESSAGE) from None
ConnectionError: Failed to connect to Ollama. Please check that Ollama is downloaded, running and accessible. https://ollama.com/download
2025-07-11 22:31:00,006 [ERROR] Ollama attempt 3 error: Failed to connect to Ollama. Please check that Ollama is downloaded, running and accessible. https://ollama.com/download
Traceback (most recent call last):
  File "C:\Users\HP\Desktop\Ollama-Chess_GUI\grok_chess.py", line 1353, in cached_ollama_move
    response = ollama.generate(
               ^^^^^^^^^^^^^^^^
  File "C:\Users\HP\anaconda3\Lib\site-packages\ollama\_client.py", line 247, in generate
    return self._request(
           ^^^^^^^^^^^^^^
  File "C:\Users\HP\anaconda3\Lib\site-packages\ollama\_client.py", line 180, in _request
    return cls(**self._request_raw(*args, **kwargs).json())
                 ^^^^^^^^^^^^^^^^^^^^^^^^^^^^^^^^^^
  File "C:\Users\HP\anaconda3\Lib\site-packages\ollama\_client.py", line 126, in _request_raw
    raise ConnectionError(CONNECTION_ERROR_MESSAGE) from None
ConnectionError: Failed to connect to Ollama. Please check that Ollama is downloaded, running and accessible. https://ollama.com/download
2025-07-11 22:31:00,007 [ERROR] Ollama failed: Ollama failed to provide valid move
Traceback (most recent call last):
  File "C:\Users\HP\Desktop\Ollama-Chess_GUI\grok_chess.py", line 1497, in get_ai_move
    raise ChessError("Ollama failed to provide valid move")
ChessError: Ollama failed to provide valid move
2025-07-11 22:31:00,010 [INFO] Stockfish move: b8c6
2025-07-11 22:31:00,019 [INFO] AI move took 9.13 seconds
2025-07-11 22:32:00,443 [INFO] Clicked square: b1
2025-07-11 22:32:00,444 [INFO] Selected piece: N at b1
2025-07-11 22:32:01,242 [INFO] Clicked square: c3
2025-07-11 22:32:43,592 [INFO] HTTP Request: POST http://127.0.0.1:11434/api/generate "HTTP/1.1 200 OK"
2025-07-11 22:32:43,607 [WARNING] Ollama attempt 1 failed: Invalid response format
2025-07-11 22:32:50,219 [INFO] HTTP Request: POST http://127.0.0.1:11434/api/generate "HTTP/1.1 200 OK"
2025-07-11 22:32:50,221 [WARNING] Ollama attempt 2 failed: Invalid response format
2025-07-11 22:32:57,094 [INFO] HTTP Request: POST http://127.0.0.1:11434/api/generate "HTTP/1.1 200 OK"
2025-07-11 22:32:57,095 [INFO] Ollama move: g8f6
2025-07-11 22:32:57,105 [INFO] AI move took 55.35 seconds
2025-07-11 22:33:14,052 [ERROR] Create PGN game error: module 'chess' has no attribute 'pgn'
Traceback (most recent call last):
  File "C:\Users\HP\Desktop\Ollama-Chess_GUI\grok_chess.py", line 717, in create_pgn_game
    game = chess.pgn.Game()
           ^^^^^^^^^
AttributeError: module 'chess' has no attribute 'pgn'
2025-07-11 22:33:14,052 [ERROR] Failed to auto-save PGN: module 'chess' has no attribute 'pgn'
Traceback (most recent call last):
  File "C:\Users\HP\Desktop\Ollama-Chess_GUI\grok_chess.py", line 717, in create_pgn_game
    game = chess.pgn.Game()
           ^^^^^^^^^
AttributeError: module 'chess' has no attribute 'pgn'

During handling of the above exception, another exception occurred:

Traceback (most recent call last):
  File "C:\Users\HP\Desktop\Ollama-Chess_GUI\grok_chess.py", line 701, in auto_save_pgn
    game = self.create_pgn_game()
           ^^^^^^^^^^^^^^^^^^^^^^
  File "C:\Users\HP\Desktop\Ollama-Chess_GUI\grok_chess.py", line 746, in create_pgn_game
    return chess.pgn.Game()
           ^^^^^^^^^
AttributeError: module 'chess' has no attribute 'pgn'
2025-07-11 22:34:23,012 [INFO] Added/Updated comment for move 4: good move...
2025-07-11 22:35:49,272 [INFO] AI difficulty set to hard
2025-07-11 22:37:54,476 [ERROR] On closing error: engine event loop dead
Traceback (most recent call last):
  File "C:\Users\HP\Desktop\Ollama-Chess_GUI\grok_chess.py", line 551, in on_closing
    self.engine.quit()
  File "C:\Users\HP\anaconda3\Lib\site-packages\chess\engine.py", line 3011, in quit
    with self._not_shut_down():
         ^^^^^^^^^^^^^^^^^^^^^
  File "C:\Users\HP\anaconda3\Lib\contextlib.py", line 137, in __enter__
    return next(self.gen)
           ^^^^^^^^^^^^^^
  File "C:\Users\HP\anaconda3\Lib\site-packages\chess\engine.py", line 2931, in _not_shut_down
    raise EngineTerminatedError("engine event loop dead")
chess.engine.EngineTerminatedError: engine event loop dead
2025-07-11 22:49:29,774 [INFO] Initializing ChessVsAI
2025-07-11 22:49:29,986 [INFO] Stockfish loaded successfully
2025-07-11 22:49:31,834 [INFO] Clicked square: e2
2025-07-11 22:49:31,834 [INFO] Selected piece: P at e2
2025-07-11 22:49:32,687 [INFO] Clicked square: e4
2025-07-11 22:50:33,432 [INFO] HTTP Request: POST http://127.0.0.1:11434/api/generate "HTTP/1.1 200 OK"
2025-07-11 22:50:33,446 [WARNING] Ollama attempt 1 failed: Invalid response format
2025-07-11 22:50:41,310 [INFO] HTTP Request: POST http://127.0.0.1:11434/api/generate "HTTP/1.1 200 OK"
2025-07-11 22:50:41,312 [WARNING] Ollama attempt 2 failed: Move g8e7 not in legal moves
2025-07-11 22:50:49,460 [INFO] HTTP Request: POST http://127.0.0.1:11434/api/generate "HTTP/1.1 200 OK"
2025-07-11 22:50:49,461 [WARNING] Ollama attempt 3 failed: Move g8e7 not in legal moves
2025-07-11 22:50:49,462 [ERROR] Ollama failed: Ollama failed to provide valid move
Traceback (most recent call last):
  File "C:\Users\HP\Desktop\Ollama-Chess_GUI\grok_chess.py", line 1497, in get_ai_move
    raise ChessError("Ollama failed to provide valid move")
ChessError: Ollama failed to provide valid move
2025-07-11 22:50:49,468 [INFO] Stockfish move: e7e5
2025-07-11 22:50:49,483 [INFO] AI move took 76.15 seconds
2025-07-11 22:52:52,347 [INFO] Clicked square: g1
2025-07-11 22:52:52,348 [INFO] Selected piece: N at g1
2025-07-11 22:52:53,304 [INFO] Clicked square: f3
2025-07-11 22:53:34,456 [INFO] HTTP Request: POST http://127.0.0.1:11434/api/generate "HTTP/1.1 200 OK"
2025-07-11 22:53:34,457 [WARNING] Ollama attempt 1 failed: Invalid response format
2025-07-11 22:53:41,607 [INFO] HTTP Request: POST http://127.0.0.1:11434/api/generate "HTTP/1.1 200 OK"
2025-07-11 22:53:41,608 [INFO] Ollama move: g8f6
2025-07-11 22:53:41,642 [INFO] AI move took 47.82 seconds
2025-07-11 22:55:59,133 [ERROR] Create PGN game error: module 'chess' has no attribute 'pgn'
Traceback (most recent call last):
  File "C:\Users\HP\Desktop\Ollama-Chess_GUI\grok_chess.py", line 717, in create_pgn_game
    game = chess.pgn.Game()
           ^^^^^^^^^
AttributeError: module 'chess' has no attribute 'pgn'
2025-07-11 22:55:59,135 [ERROR] Failed to auto-save PGN: module 'chess' has no attribute 'pgn'
Traceback (most recent call last):
  File "C:\Users\HP\Desktop\Ollama-Chess_GUI\grok_chess.py", line 717, in create_pgn_game
    game = chess.pgn.Game()
           ^^^^^^^^^
AttributeError: module 'chess' has no attribute 'pgn'

During handling of the above exception, another exception occurred:

Traceback (most recent call last):
  File "C:\Users\HP\Desktop\Ollama-Chess_GUI\grok_chess.py", line 701, in auto_save_pgn
    game = self.create_pgn_game()
           ^^^^^^^^^^^^^^^^^^^^^^
  File "C:\Users\HP\Desktop\Ollama-Chess_GUI\grok_chess.py", line 746, in create_pgn_game
    return chess.pgn.Game()
           ^^^^^^^^^
AttributeError: module 'chess' has no attribute 'pgn'
2025-07-11 22:56:07,333 [INFO] Added/Updated comment for move 4: AI (Ollama): This move develops a piece while also...
